Workbook
Name Branch_List: Locations[Branch_ID]
Name Emp_List: Employees[Employee_ID]
Name SKU_List: Products[SKU]
Name Slicer_Branch_Name: #N/A
Name Slicer_Branch_Name1: #N/A
Name Slicer_Category: #N/A
Name Slicer_Category1: #N/A
Name Slicer_Color: #N/A
Name Slicer_Product_Name: #N/A
Name Slicer_Size: #N/A
Name Timeline_Date: #N/A

Sheet PriceList
A1: Branch_ID | B1: SKU | C1: Unit_Cost_EGP | D1: Unit_Retail_Price_EGP | E1: Key
A2: BR02 | B2: DRS-SMR-RED-L | C2: 490 | D2: 1159 | E2: =PriceList[[#This Row],[SKU]] & "|" & PriceList[[#This Row],[Branch_ID]] -> DRS-SMR-RED-L|BR02
A3: BR03 | B3: DRS-SMR-NVY-L | C3: 480 | D3: 1129 | E3: =PriceList[[#This Row],[SKU]] & "|" & PriceList[[#This Row],[Branch_ID]] -> DRS-SMR-NVY-L|BR03
A4: BR04 | B4: TSH-CRW-RED-S | C4: 135 | D4: 329 | E4: =PriceList[[#This Row],[SKU]] & "|" & PriceList[[#This Row],[Branch_ID]] -> TSH-CRW-RED-S|BR04
A5: BR04 | B5: JKT-DNM-BLK-M | C5: 625 | D5: 1409 | E5: =PriceList[[#This Row],[SKU]] & "|" & PriceList[[#This Row],[Branch_ID]] -> JKT-DNM-BLK-M|BR04
A6: BR03 | B6: PNT-JNS-BLK-34 | C6: 420 | D6: 1029 | E6: =PriceList[[#This Row],[SKU]] & "|" & PriceList[[#This Row],[Branch_ID]] -> PNT-JNS-BLK-34|BR03
A7: BR02 | B7: SHO-SPT-NVY-XL | C7: 185 | D7: 479 | E7: =PriceList[[#This Row],[SKU]] & "|" & PriceList[[#This Row],[Branch_ID]] -> SHO-SPT-NVY-XL|BR02
A8: BR01 | B8: PNT-CHN-BEG-30 | C8: 390 | D8: 1009 | E8: =PriceList[[#This Row],[SKU]] & "|" & PriceList[[#This Row],[Branch_ID]] -> PNT-CHN-BEG-30|BR01
A9: BR01 | B9: TSH-POL-WHT-L | C9: 225 | D9: 609 | E9: =PriceList[[#This Row],[SKU]] & "|" & PriceList[[#This Row],[Branch_ID]] -> TSH-POL-WHT-L|BR01
A10: BR02 | B10: CAP-BSB-WHT-OS | C10: 110 | D10: 299 | E10: =PriceList[[#This Row],[SKU]] & "|" & PriceList[[#This Row],[Branch_ID]] -> CAP-BSB-WHT-OS|BR02
A11: BR03 | B11: HOD-PLV-BLK-L | C11: 460 | D11: 1129 | E11: =PriceList[[#This Row],[SKU]] & "|" & PriceList[[#This Row],[Branch_ID]] -> HOD-PLV-BLK-L|BR03
A12: BR05 | B12: JKT-BMB-OLV-S | C12: 730 | D12: 1729 | E12: =PriceList[[#This Row],[SKU]] & "|" & PriceList[[#This Row],[Branch_ID]] -> JKT-BMB-OLV-S|BR05
A13: BR04 | B13: HOD-ZIP-OLV-S | C13: 510 | D13: 1129 | E13: =PriceList[[#This Row],[SKU]] & "|" & PriceList[[#This Row],[Branch_ID]] -> HOD-ZIP-OLV-S|BR04
... A663: BR01 | B663: PNT-CHN-BEG-36 | C663: 390 | D663: 1009 | E663: =PriceList[[#This Row],[SKU]] & "|" & PriceList[[#This Row],[Branch_ID]] -> PNT-CHN-BEG-36|BR01

Sheet Inventory_Log
A1: Transaction_ID | B1: Date | C1: Time | D1: Shift | E1: Transaction_Type | F1: Branch_ID | G1: Branch_Name | H1: City | I1: Country | J1: Employee_ID | K1: Employee_Name | L1: SKU | M1: Category | N1: Product_Name | O1: Color | P1: Size | Q1: Quantity | R1: Unit_Cost_EGP | S1: Unit_Retail_Price_EGP
A2: TXN-000001 | B2: 45809 | C2: 09:15 | D2: Morning | E2: Restock | F2: BR02 | G2: City Stars Nasr City | H2: Cairo | I2: Egypt | J2: EMP04 | K2: Youssef Ibrahim | L2: DRS-SMR-RED-L | M2: Dress | N2: Summer Dress | O2: Red | P2: L | Q2: 17 | R2: 490 | S2: 1159
A3: TXN-000002 | B3: 45809 | C3: 09:15 | D3: Morning | E3: Restock | F3: BR03 | G3: San Stefano Alexandria | H3: Alexandria | I3: Egypt | J3: EMP07 | K3: Nourhan Tarek | L3: DRS-SMR-NVY-L | M3: Dress | N3: Summer Dress | O3: Navy | P3: L | Q3: 19 | R3: 480 | S3: 1129
A4: TXN-000003 | B4: 45809 | C4: 09:15 | D4: Morning | E4: Restock | F4: BR04 | G4: Mansoura Downtown | H4: Mansoura | I4: Egypt | J4: EMP10 | K4: Mostafa Gamal | L4: TSH-CRW-RED-S | M4: T-Shirt | N4: Classic Crew Tee | O4: Red | P4: S | Q4: 26 | R4: 135 | S4: 329
A5: TXN-000004 | B5: 45809 | C5: 09:15 | D5: Morning | E5: Restock | F5: BR04 | G5: Mansoura Downtown | H5: Mansoura | I5: Egypt | J5: EMP10 | K5: Mostafa Gamal | L5: JKT-DNM-BLK-M | M5: Jacket | N5: Denim Jacket | O5: Black | P5: M | Q5: 21 | R5: 625 | S5: 1409
A6: TXN-000005 | B6: 45809 | C6: 09:15 | D6: Morning | E6: Restock | F6: BR03 | G6: San Stefano Alexandria | H6: Alexandria | I6: Egypt | J6: EMP07 | K6: Nourhan Tarek | L6: PNT-JNS-BLK-34 | M6: Pants | N6: Slim Fit Jeans | O6: Black | P6: 34 | Q6: 30 | R6: 420 | S6: 1029
A7: TXN-000006 | B7: 45809 | C7: 09:15 | D7: Morning | E7: Restock | F7: BR02 | G7: City Stars Nasr City | H7: Cairo | I7: Egypt | J7: EMP04 | K7: Youssef Ibrahim | L7: SHO-SPT-NVY-XL | M7: Shorts | N7: Sport Shorts | O7: Navy | P7: XL | Q7: 11 | R7: 185 | S7: 479
A8: TXN-000007 | B8: 45809 | C8: 09:15 | D8: Morning | E8: Restock | F8: BR01 | G8: Cairo Festival City | H8: Cairo | I8: Egypt | J8: EMP01 | K8: Ahmed Hassan | L8: PNT-CHN-BEG-30 | M8: Pants | N8: Chino Pants | O8: Beige | P8: 30 | Q8: 15 | R8: 390 | S8: 1009
A9: TXN-000008 | B9: 45809 | C9: 09:15 | D9: Morning | E9: Restock | F9: BR01 | G9: Cairo Festival City | H9: Cairo | I9: Egypt | J9: EMP01 | K9: Ahmed Hassan | L9: TSH-POL-WHT-L | M9: T-Shirt | N9: Polo Shirt | O9: White | P9: L | Q9: 47 | R9: 225 | S9: 609
A10: TXN-000009 | B10: 45809 | C10: 09:15 | D10: Morning | E10: Restock | F10: BR02 | G10: City Stars Nasr City | H10: Cairo | I10: Egypt | J10: EMP04 | K10: Youssef Ibrahim | L10: CAP-BSB-WHT-OS | M10: Cap | N10: Baseball Cap | O10: White | P10: OS | Q10: 18 | R10: 110 | S10: 299
A11: TXN-000010 | B11: 45809 | C11: 09:15 | D11: Morning | E11: Restock | F11: BR03 | G11: San Stefano Alexandria | H11: Alexandria | I11: Egypt | J11: EMP07 | K11: Nourhan Tarek | L11: HOD-PLV-BLK-L | M11: Hoodie | N11: Pullover Hoodie | O11: Black | P11: L | Q11: 28 | R11: 460 | S11: 1129
A12: TXN-000011 | B12: 45809 | C12: 09:15 | D12: Morning | E12: Restock | F12: BR05 | G12: Senzo Mall Hurghada | H12: Hurghada | I12: Egypt | J12: EMP13 | K12: Heba Mohamed | L12: JKT-BMB-OLV-S | M12: Jacket | N12: Bomber Jacket | O12: Olive | P12: S | Q12: 15 | R12: 730 | S12: 1729
A13: TXN-000012 | B13: 45809 | C13: 09:15 | D13: Morning | E13: Restock | F13: BR04 | G13: Mansoura Downtown | H13: Mansoura | I13: Egypt | J13: EMP10 | K13: Mostafa Gamal | L13: HOD-ZIP-OLV-S | M13: Hoodie | N13: Zip-Up Hoodie | O13: Olive | P13: S | Q13: 14 | R13: 510 | S13: 1129
... A5737: TXN-005736 | B5737: 46173 | C5737: 21:34 | D5737: Evening | E5737: Sale | F5737: BR01 | G5737: Cairo Festival City | H5737: Cairo | I5737: Egypt | J5737: EMP03 | K5737: Omar Khaled | L5737: TSH-POL-WHT-XL | M5737: T-Shirt | N5737: Polo Shirt | O5737: White | P5737: XL | Q5737: 1 | R5737: 225 | S5737: 609

Sheet Ledger
A1: Transaction_ID | B1: Date | C1: Time | D1: Shift | E1: Transaction_Type | F1: Branch_ID | G1: Employee_ID | H1: SKU | I1: Quantity | J1: Unit_Cost_EGP | K1: Unit_Retail_Price_EGP | L1: Date (Year) | M1: Date (Quarter) | N1: Date (Month Index) | O1: Date (Month)
A2: TXN-000679 | B2: 45810 | C2: 0.66944444 | D2: =_xlfn.XLOOKUP(Ledger[[#This Row],[Employee_ID]],Employees!C:C,Employees!A:A) -> Afternoon | E2: Sale | F2: =_xlfn.XLOOKUP(Ledger[[#This Row],[Employee_ID]],Employees!C:C,Employees!B:B) -> BR01 | G2: EMP02 | H2: TSH-CRW-RED-S | I2: 1 | J2: =_xlfn.XLOOKUP(Ledger[[#This Row],[SKU]]&"|"&Ledger[[#This Row],[Branch_ID]], PriceList!E:E,PriceList!C:C,"") -> 145 | K2: =_xlfn.XLOOKUP(Ledger[[#This Row],[SKU]]&"|"&Ledger[[#This Row],[Branch_ID]], PriceList[Key], PriceList[Unit_Retail_Price_EGP], "") -> 389 | L2: =YEAR(Ledger[[#This Row],[Date]]) -> 2025 | M2: ="Qtr"&ROUNDUP(MONTH(Ledger[[#This Row],[Date]])/3,0) -> Qtr2 | N2: =MONTH(Ledger[[#This Row],[Date]]) -> 6 | O2: =TEXT(Ledger[[#This Row],[Date]],"mmm") -> Jun
A3: TXN-000714 | B3: 45813 | C3: 0.70347222 | D3: =_xlfn.XLOOKUP(Ledger[[#This Row],[Employee_ID]],Employees!C:C,Employees!A:A) -> Afternoon | E3: Sale | F3: =_xlfn.XLOOKUP(Ledger[[#This Row],[Employee_ID]],Employees!C:C,Employees!B:B) -> BR01 | G3: EMP02 | H3: TSH-CRW-NVY-XL | I3: 1 | J3: =_xlfn.XLOOKUP(Ledger[[#This Row],[SKU]]&"|"&Ledger[[#This Row],[Branch_ID]], PriceList!E:E,PriceList!C:C,"") -> 145 | K3: =_xlfn.XLOOKUP(Ledger[[#This Row],[SKU]]&"|"&Ledger[[#This Row],[Branch_ID]], PriceList[Key], PriceList[Unit_Retail_Price_EGP], "") -> 389 | L3: =YEAR(Ledger[[#This Row],[Date]]) -> 2025 | M3: ="Qtr"&ROUNDUP(MONTH(Ledger[[#This Row],[Date]])/3,0) -> Qtr2 | N3: =MONTH(Ledger[[#This Row],[Date]]) -> 6 | O3: =TEXT(Ledger[[#This Row],[Date]],"mmm") -> Jun
A4: TXN-000720 | B4: 45814 | C4: 0.6 | D4: =_xlfn.XLOOKUP(Ledger[[#This Row],[Employee_ID]],Employees!C:C,Employees!A:A) -> Afternoon | E4: Sale | F4: =_xlfn.XLOOKUP(Ledger[[#This Row],[Employee_ID]],Employees!C:C,Employees!B:B) -> BR01 | G4: EMP02 | H4: TSH-CRW-RED-M | I4: 1 | J4: =_xlfn.XLOOKUP(Ledger[[#This Row],[SKU]]&"|"&Ledger[[#This Row],[Branch_ID]], PriceList!E:E,PriceList!C:C,"") -> 145 | K4: =_xlfn.XLOOKUP(Ledger[[#This Row],[SKU]]&"|"&Ledger[[#This Row],[Branch_ID]], PriceList[Key], PriceList[Unit_Retail_Price_EGP], "") -> 389 | L4: =YEAR(Ledger[[#This Row],[Date]]) -> 2025 | M4: ="Qtr"&ROUNDUP(MONTH(Ledger[[#This Row],[Date]])/3,0) -> Qtr2 | N4: =MONTH(Ledger[[#This Row],[Date]]) -> 6 | O4: =TEXT(Ledger[[#This Row],[Date]],"mmm") -> Jun
A5: TXN-000854 | B5: 45823 | C5: 0.72638889 | D5: =_xlfn.XLOOKUP(Ledger[[#This Row],[Employee_ID]],Employees!C:C,Employees!A:A) -> Afternoon | E5: Sale | F5: =_xlfn.XLOOKUP(Ledger[[#This Row],[Employee_ID]],Employees!C:C,Employees!B:B) -> BR01 | G5: EMP02 | H5: TSH-CRW-RED-S | I5: 1 | J5: =_xlfn.XLOOKUP(Ledger[[#This Row],[SKU]]&"|"&Ledger[[#This Row],[Branch_ID]], PriceList!E:E,PriceList!C:C,"") -> 145 | K5: =_xlfn.XLOOKUP(Ledger[[#This Row],[SKU]]&"|"&Ledger[[#This Row],[Branch_ID]], PriceList[Key], PriceList[Unit_Retail_Price_EGP], "") -> 389 | L5: =YEAR(Ledger[[#This Row],[Date]]) -> 2025 | M5: ="Qtr"&ROUNDUP(MONTH(Ledger[[#This Row],[Date]])/3,0) -> Qtr2 | N5: =MONTH(Ledger[[#This Row],[Date]]) -> 6 | O5: =TEXT(Ledger[[#This Row],[Date]],"mmm") -> Jun
A6: TXN-000957 | B6: 45831 | C6: 0.72777778 | D6: =_xlfn.XLOOKUP(Ledger[[#This Row],[Employee_ID]],Employees!C:C,Employees!A:A) -> Afternoon | E6: Sale | F6: =_xlfn.XLOOKUP(Ledger[[#This Row],[Employee_ID]],Employees!C:C,Employees!B:B) -> BR01 | G6: EMP02 | H6: TSH-CRW-WHT-L | I6: 1 | J6: =_xlfn.XLOOKUP(Ledger[[#This Row],[SKU]]&"|"&Ledger[[#This Row],[Branch_ID]], PriceList!E:E,PriceList!C:C,"") -> 145 | K6: =_xlfn.XLOOKUP(Ledger[[#This Row],[SKU]]&"|"&Ledger[[#This Row],[Branch_ID]], PriceList[Key], PriceList[Unit_Retail_Price_EGP], "") -> 389 | L6: =YEAR(Ledger[[#This Row],[Date]]) -> 2025 | M6: ="Qtr"&ROUNDUP(MONTH(Ledger[[#This Row],[Date]])/3,0) -> Qtr2 | N6: =MONTH(Ledger[[#This Row],[Date]]) -> 6 | O6: =TEXT(Ledger[[#This Row],[Date]],"mmm") -> Jun
A7: TXN-001207 | B7: 45850 | C7: 0.60486111 | D7: =_xlfn.XLOOKUP(Ledger[[#This Row],[Employee_ID]],Employees!C:C,Employees!A:A) -> Afternoon | E7: Sale | F7: =_xlfn.XLOOKUP(Ledger[[#This Row],[Employee_ID]],Employees!C:C,Employees!B:B) -> BR01 | G7: EMP02 | H7: TSH-CRW-BLK-S | I7: 1 | J7: =_xlfn.XLOOKUP(Ledger[[#This Row],[SKU]]&"|"&Ledger[[#This Row],[Branch_ID]], PriceList!E:E,PriceList!C:C,"") -> 145 | K7: =_xlfn.XLOOKUP(Ledger[[#This Row],[SKU]]&"|"&Ledger[[#This Row],[Branch_ID]], PriceList[Key], PriceList[Unit_Retail_Price_EGP], "") -> 389 | L7: =YEAR(Ledger[[#This Row],[Date]]) -> 2025 | M7: ="Qtr"&ROUNDUP(MONTH(Ledger[[#This Row],[Date]])/3,0) -> Qtr3 | N7: =MONTH(Ledger[[#This Row],[Date]]) -> 7 | O7: =TEXT(Ledger[[#This Row],[Date]],"mmm") -> Jul
A8: TXN-001234 | B8: 45852 | C8: 0.69652778 | D8: =_xlfn.XLOOKUP(Ledger[[#This Row],[Employee_ID]],Employees!C:C,Employees!A:A) -> Afternoon | E8: Sale | F8: =_xlfn.XLOOKUP(Ledger[[#This Row],[Employee_ID]],Employees!C:C,Employees!B:B) -> BR01 | G8: EMP02 | H8: TSH-CRW-WHT-L | I8: 1 | J8: =_xlfn.XLOOKUP(Ledger[[#This Row],[SKU]]&"|"&Ledger[[#This Row],[Branch_ID]], PriceList!E:E,PriceList!C:C,"") -> 145 | K8: =_xlfn.XLOOKUP(Ledger[[#This Row],[SKU]]&"|"&Ledger[[#This Row],[Branch_ID]], PriceList[Key], PriceList[Unit_Retail_Price_EGP], "") -> 389 | L8: =YEAR(Ledger[[#This Row],[Date]]) -> 2025 | M8: ="Qtr"&ROUNDUP(MONTH(Ledger[[#This Row],[Date]])/3,0) -> Qtr3 | N8: =MONTH(Ledger[[#This Row],[Date]]) -> 7 | O8: =TEXT(Ledger[[#This Row],[Date]],"mmm") -> Jul
A9: TXN-001245 | B9: 45853 | C9: 0.70138889 | D9: =_xlfn.XLOOKUP(Ledger[[#This Row],[Employee_ID]],Employees!C:C,Employees!A:A) -> Afternoon | E9: Sale | F9: =_xlfn.XLOOKUP(Ledger[[#This Row],[Employee_ID]],Employees!C:C,Employees!B:B) -> BR01 | G9: EMP02 | H9: TSH-CRW-RED-L | I9: 1 | J9: =_xlfn.XLOOKUP(Ledger[[#This Row],[SKU]]&"|"&Ledger[[#This Row],[Branch_ID]], PriceList!E:E,PriceList!C:C,"") -> 145 | K9: =_xlfn.XLOOKUP(Ledger[[#This Row],[SKU]]&"|"&Ledger[[#This Row],[Branch_ID]], PriceList[Key], PriceList[Unit_Retail_Price_EGP], "") -> 389 | L9: =YEAR(Ledger[[#This Row],[Date]]) -> 2025 | M9: ="Qtr"&ROUNDUP(MONTH(Ledger[[#This Row],[Date]])/3,0) -> Qtr3 | N9: =MONTH(Ledger[[#This Row],[Date]]) -> 7 | O9: =TEXT(Ledger[[#This Row],[Date]],"mmm") -> Jul
A10: TXN-001270 | B10: 45855 | C10: 0.73263889 | D10: =_xlfn.XLOOKUP(Ledger[[#This Row],[Employee_ID]],Employees!C:C,Employees!A:A) -> Afternoon | E10: Sale | F10: =_xlfn.XLOOKUP(Ledger[[#This Row],[Employee_ID]],Employees!C:C,Employees!B:B) -> BR01 | G10: EMP02 | H10: TSH-CRW-NVY-XL | I10: 1 | J10: =_xlfn.XLOOKUP(Ledger[[#This Row],[SKU]]&"|"&Ledger[[#This Row],[Branch_ID]], PriceList!E:E,PriceList!C:C,"") -> 145 | K10: =_xlfn.XLOOKUP(Ledger[[#This Row],[SKU]]&"|"&Ledger[[#This Row],[Branch_ID]], PriceList[Key], PriceList[Unit_Retail_Price_EGP], "") -> 389 | L10: =YEAR(Ledger[[#This Row],[Date]]) -> 2025 | M10: ="Qtr"&ROUNDUP(MONTH(Ledger[[#This Row],[Date]])/3,0) -> Qtr3 | N10: =MONTH(Ledger[[#This Row],[Date]]) -> 7 | O10: =TEXT(Ledger[[#This Row],[Date]],"mmm") -> Jul
A11: TXN-001330 | B11: 45859 | C11: 0.67152778 | D11: =_xlfn.XLOOKUP(Ledger[[#This Row],[Employee_ID]],Employees!C:C,Employees!A:A) -> Afternoon | E11: Sale | F11: =_xlfn.XLOOKUP(Ledger[[#This Row],[Employee_ID]],Employees!C:C,Employees!B:B) -> BR01 | G11: EMP02 | H11: TSH-CRW-WHT-L | I11: 1 | J11: =_xlfn.XLOOKUP(Ledger[[#This Row],[SKU]]&"|"&Ledger[[#This Row],[Branch_ID]], PriceList!E:E,PriceList!C:C,"") -> 145 | K11: =_xlfn.XLOOKUP(Ledger[[#This Row],[SKU]]&"|"&Ledger[[#This Row],[Branch_ID]], PriceList[Key], PriceList[Unit_Retail_Price_EGP], "") -> 389 | L11: =YEAR(Ledger[[#This Row],[Date]]) -> 2025 | M11: ="Qtr"&ROUNDUP(MONTH(Ledger[[#This Row],[Date]])/3,0) -> Qtr3 | N11: =MONTH(Ledger[[#This Row],[Date]]) -> 7 | O11: =TEXT(Ledger[[#This Row],[Date]],"mmm") -> Jul
A12: TXN-001331 | B12: 45859 | C12: 0.67847222 | D12: =_xlfn.XLOOKUP(Ledger[[#This Row],[Employee_ID]],Employees!C:C,Employees!A:A) -> Afternoon | E12: Sale | F12: =_xlfn.XLOOKUP(Ledger[[#This Row],[Employee_ID]],Employees!C:C,Employees!B:B) -> BR01 | G12: EMP02 | H12: TSH-CRW-WHT-L | I12: 1 | J12: =_xlfn.XLOOKUP(Ledger[[#This Row],[SKU]]&"|"&Ledger[[#This Row],[Branch_ID]], PriceList!E:E,PriceList!C:C,"") -> 145 | K12: =_xlfn.XLOOKUP(Ledger[[#This Row],[SKU]]&"|"&Ledger[[#This Row],[Branch_ID]], PriceList[Key], PriceList[Unit_Retail_Price_EGP], "") -> 389 | L12: =YEAR(Ledger[[#This Row],[Date]]) -> 2025 | M12: ="Qtr"&ROUNDUP(MONTH(Ledger[[#This Row],[Date]])/3,0) -> Qtr3 | N12: =MONTH(Ledger[[#This Row],[Date]]) -> 7 | O12: =TEXT(Ledger[[#This Row],[Date]],"mmm") -> Jul
A13: TXN-001381 | B13: 45863 | C13: 0.60972222 | D13: =_xlfn.XLOOKUP(Ledger[[#This Row],[Employee_ID]],Employees!C:C,Employees!A:A) -> Afternoon | E13: Sale | F13: =_xlfn.XLOOKUP(Ledger[[#This Row],[Employee_ID]],Employees!C:C,Employees!B:B) -> BR01 | G13: EMP02 | H13: TSH-CRW-BLK-M | I13: 1 | J13: =_xlfn.XLOOKUP(Ledger[[#This Row],[SKU]]&"|"&Ledger[[#This Row],[Branch_ID]], PriceList!E:E,PriceList!C:C,"") -> 145 | K13: =_xlfn.XLOOKUP(Ledger[[#This Row],[SKU]]&"|"&Ledger[[#This Row],[Branch_ID]], PriceList[Key], PriceList[Unit_Retail_Price_EGP], "") -> 389 | L13: =YEAR(Ledger[[#This Row],[Date]]) -> 2025 | M13: ="Qtr"&ROUNDUP(MONTH(Ledger[[#This Row],[Date]])/3,0) -> Qtr3 | N13: =MONTH(Ledger[[#This Row],[Date]]) -> 7 | O13: =TEXT(Ledger[[#This Row],[Date]],"mmm") -> Jul
... A5737: TXN-000662 | B5737: 45809 | C5737: 0.40625 | D5737: =_xlfn.XLOOKUP(Ledger[[#This Row],[Employee_ID]],Employees!C:C,Employees!A:A) -> Morning | E5737: Restock | F5737: =_xlfn.XLOOKUP(Ledger[[#This Row],[Employee_ID]],Employees!C:C,Employees!B:B) -> BR01 | G5737: EMP01 | H5737: PNT-CHN-BEG-36 | I5737: 16 | J5737: =_xlfn.XLOOKUP(Ledger[[#This Row],[SKU]]&"|"&Ledger[[#This Row],[Branch_ID]], PriceList!E:E,PriceList!C:C,"") -> 390 | K5737: =_xlfn.XLOOKUP(Ledger[[#This Row],[SKU]]&"|"&Ledger[[#This Row],[Branch_ID]], PriceList[Key], PriceList[Unit_Retail_Price_EGP], "") -> 1009 | L5737: =YEAR(Ledger[[#This Row],[Date]]) -> 2025 | M5737: ="Qtr"&ROUNDUP(MONTH(Ledger[[#This Row],[Date]])/3,0) -> Qtr2 | N5737: =MONTH(Ledger[[#This Row],[Date]]) -> 6 | O5737: =TEXT(Ledger[[#This Row],[Date]],"mmm") -> Jun

Sheet Employees
A1: Shift | B1: Branch_ID | C1: Employee_ID | D1: Employee_Name
A2: Morning | B2: BR01 | C2: EMP01 | D2: Ahmed Hassan
A3: Afternoon | B3: BR01 | C3: EMP02 | D3: Mariam Adel
A4: Evening | B4: BR01 | C4: EMP03 | D4: Omar Khaled
A5: Morning | B5: BR02 | C5: EMP04 | D5: Youssef Ibrahim
A6: Afternoon | B6: BR02 | C6: EMP05 | D6: Salma Mostafa
A7: Evening | B7: BR02 | C7: EMP06 | D7: Khaled Sami
A8: Morning | B8: BR03 | C8: EMP07 | D8: Nourhan Tarek
A9: Afternoon | B9: BR03 | C9: EMP08 | D9: Mahmoud Fathy
A10: Evening | B10: BR03 | C10: EMP09 | D10: Yasmin Ali
A11: Morning | B11: BR04 | C11: EMP10 | D11: Mostafa Gamal
A12: Afternoon | B12: BR04 | C12: EMP11 | D12: Dina Ashraf
... A16: Evening | B16: BR05 | C16: EMP15 | D16: Aya Magdy

Sheet Locations
A1: Branch_ID | B1: Branch_Name | C1: City | D1: Country
A2: BR02 | B2: City Stars Nasr City | C2: Cairo | D2: Egypt
A3: BR03 | B3: San Stefano Alexandria | C3: Alexandria | D3: Egypt
A4: BR04 | B4: Mansoura Downtown | C4: Mansoura | D4: Egypt
A5: BR01 | B5: Cairo Festival City | C5: Cairo | D5: Egypt
A6: BR05 | B6: Senzo Mall Hurghada | C6: Hurghada | D6: Egypt

Sheet Products
A1: SKU | B1: Category | C1: Product_Name | D1: Color | E1: Size
A2: CAP-BSB-BLK-OS | B2: Cap | C2: Baseball Cap | D2: Black | E2: OS
A3: CAP-BSB-NVY-OS | B3: Cap | C3: Baseball Cap | D3: Navy | E3: OS
A4: CAP-BSB-RED-OS | B4: Cap | C4: Baseball Cap | D4: Red | E4: OS
A5: CAP-BSB-WHT-OS | B5: Cap | C5: Baseball Cap | D5: White | E5: OS
A6: CAP-SNP-BLK-OS | B6: Cap | C6: Snapback Cap | D6: Black | E6: OS
A7: CAP-SNP-GRY-OS | B7: Cap | C7: Snapback Cap | D7: Grey | E7: OS
A8: DRS-SMR-BLK-L | B8: Dress | C8: Summer Dress | D8: Black | E8: L
A9: DRS-SMR-BLK-M | B9: Dress | C9: Summer Dress | D9: Black | E9: M
A10: DRS-SMR-BLK-S | B10: Dress | C10: Summer Dress | D10: Black | E10: S
A11: DRS-SMR-NVY-L | B11: Dress | C11: Summer Dress | D11: Navy | E11: L
A12: DRS-SMR-NVY-M | B12: Dress | C12: Summer Dress | D12: Navy | E12: M
... A149: TSH-POL-WHT-XL | B149: T-Shirt | C149: Polo Shirt | D149: White | E149: XL

Sheet Pivots
A3: Row Labels | B3: Sales Revenue | C3: Gross Profit
A4: Jan | B4: 484586 | C4: 288041
A5: Feb | B5: 398140 | C5: 236885
A6: Mar | B6: 398892 | C6: 238972
A7: Apr | B7: 396591 | C7: 236206
A8: May | B8: 357811 | C8: 214271
A9: Jun | B9: 303143 | C9: 182908
A10: Jul | B10: 327442 | C10: 197392
A11: Aug | B11: 349345 | C11: 210165
A12: Sep | B12: 359968 | C12: 215928
A13: Oct | B13: 402732 | C13: 240632
A14: Nov | B14: 411501 | C14: 244811
A15: Dec | B15: 455621 | C15: 270636
A16: Grand Total | B16: 4645772 | C16: 2776847
A18: Row Labels | B18: Sales Revenue | C18: Gross Profit
A19: Cairo Festival City | B19: 1344670 | C19: 827590
A20: City Stars Nasr City | B20: 1183731 | C20: 703811
A21: Mansoura Downtown | B21: 545414 | C21: 308649
A22: San Stefano Alexandria | B22: 866360 | C22: 514250
A23: Senzo Mall Hurghada | B23: 705597 | C23: 422547
A24: Grand Total | B24: 4645772 | C24: 2776847
A26: Units Sold | B26: Column Labels
A27: Row Labels | B27: Cairo Festival City | C27: City Stars Nasr City | D27: Mansoura Downtown | E27: San Stefano Alexandria | F27: Senzo Mall Hurghada | G27: Grand Total
A28: T-Shirt | B28: 922 | C28: 791 | D28: 353 | E28: 579 | F28: 487 | G28: 3132
A29: Socks | B29: 25 | C29: 15 | D29: 16 | E29: 14 | F29: 11 | G29: 81
A30: Skirt | B30: 26 | C30: 29 | D30: 15 | E30: 25 | F30: 7 | G30: 102
A31: Shorts | B31: 194 | C31: 163 | D31: 89 | E31: 150 | F31: 107 | G31: 703
A32: Pants | B32: 257 | C32: 235 | D32: 111 | E32: 158 | F32: 118 | G32: 879
A33: Jacket | B33: 72 | C33: 90 | D33: 45 | E33: 88 | F33: 39 | G33: 334
A34: Hoodie | B34: 226 | C34: 197 | D34: 148 | E34: 133 | F34: 145 | G34: 849
A35: Dress | B35: 66 | C35: 66 | D35: 21 | E35: 49 | F35: 40 | G35: 242
A36: Cap | B36: 42 | C36: 43 | D36: 28 | E36: 34 | F36: 29 | G36: 176
A37: Grand Total | B37: 1830 | C37: 1629 | D37: 826 | E37: 1230 | F37: 983 | G37: 6498
A39: Units Sold | B39: Column Labels
A40: Row Labels | B40: Cap | C40: Dress | D40: Hoodie | E40: Jacket | F40: Pants | G40: Shorts | H40: Skirt | I40: Socks | J40: T-Shirt | K40: Grand Total
A41: Cairo Festival City | B41: 42 | C41: 66 | D41: 226 | E41: 72 | F41: 257 | G41: 194 | H41: 26 | I41: 25 | J41: 922 | K41: 1830
A42: City Stars Nasr City | B42: 43 | C42: 66 | D42: 197 | E42: 90 | F42: 235 | G42: 163 | H42: 29 | I42: 15 | J42: 791 | K42: 1629
A43: Mansoura Downtown | B43: 28 | C43: 21 | D43: 148 | E43: 45 | F43: 111 | G43: 89 | H43: 15 | I43: 16 | J43: 353 | K43: 826
A44: San Stefano Alexandria | B44: 34 | C44: 49 | D44: 133 | E44: 88 | F44: 158 | G44: 150 | H44: 25 | I44: 14 | J44: 579 | K44: 1230
A45: Senzo Mall Hurghada | B45: 29 | C45: 40 | D45: 145 | E45: 39 | F45: 118 | G45: 107 | H45: 7 | I45: 11 | J45: 487 | K45: 983
...

Sheet DashBoard
B8: Units Sold
B9: 6498
B11: Units Returned
B12: 282
B14: Gross Profit
B15: 2776847
B17: Gross Margin %
B18: 0.59771487

Sheet Inventory
A1: Stock On Hand | B1: Column Labels
A2: Row Labels | B2: Cairo Festival City | C2: City Stars Nasr City | D2: Mansoura Downtown | E2: San Stefano Alexandria | F2: Senzo Mall Hurghada | G2: Grand Total
A3: Cap
A4: Baseball Cap
A5: Black | B5: 11 | C5: 13 | D5: 15 | E5: 4 | F5: 9 | G5: 52
A6: Navy | B6: 10 | C6: 8 | D6: 11 | E6: 18 | F6: 10 | G6: 57
A7: Red | B7: 12 | C7: 7 | D7: 10 | E7: 10 | F7: 4 | G7: 43
A8: White | B8: 17 | C8: 15 | D8: 15 | E8: 10 | F8: 7 | G8: 64
A9: Snapback Cap
A10: Black | B10: 4 | C10: 6 | D10: 12 | E10: 10 | F10: 14 | G10: 46
A11: Grey | B11: 14 | C11: 19 | D11: 11 | E11: 0 | F11: 4 | G11: 48
A12: Dress
A13: Summer Dress
A14: Black | B14: 41 | C14: 35 | D14: 40 | E14: 37 | F14: 34 | G14: 187
A15: Navy | B15: 24 | C15: 30 | D15: 46 | E15: 36 | F15: 45 | G15: 181
A16: Red | B16: 38 | C16: 31 | D16: 21 | E16: 32 | F16: 36 | G16: 158
A17: Hoodie
A18: Pullover Hoodie
A19: Black | B19: 48 | C19: 61 | D19: 66 | E19: 44 | F19: 94 | G19: 313
A20: Burgundy | B20: 50 | C20: 33 | D20: 41 | E20: 56 | F20: 44 | G20: 224
A21: Grey | B21: 44 | C21: 37 | D21: 44 | E21: 48 | F21: 40 | G21: 213
A22: Navy | B22: 44 | C22: 38 | D22: 52 | E22: 36 | F22: 56 | G22: 226
A23: Zip-Up Hoodie
A24: Black | B24: 58 | C24: 71 | D24: 74 | E24: 53 | F24: 55 | G24: 311
A25: Olive | B25: 30 | C25: 38 | D25: 37 | E25: 35 | F25: 41 | G25: 181
A26: Jacket
A27: Bomber Jacket
A28: Black | B28: 48 | C28: 34 | D28: 52 | E28: 34 | F28: 27 | G28: 195
A29: Olive | B29: 30 | C29: 38 | D29: 35 | E29: 48 | F29: 50 | G29: 201
A30: Denim Jacket
A31: Black | B31: 41 | C31: 27 | D31: 58 | E31: 43 | F31: 52 | G31: 221
A32: Blue | B32: 48 | C32: 45 | D32: 33 | E32: 36 | F32: 38 | G32: 200
A33: Pants
A34: Chino Pants
A35: Beige | B35: 44 | C35: 37 | D35: 8 | E35: 42 | F35: 51 | G35: 182
A36: Navy | B36: 48 | C36: 69 | D36: 72 | E36: 44 | F36: 55 | G36: 288
A37: Olive | B37: 48 | C37: 31 | D37: 41 | E37: 42 | F37: 25 | G37: 187
A38: Slim Fit Jeans
A39: Black | B39: 68 | C39: 82 | D39: 44 | E39: 74 | F39: 54 | G39: 322
A40: Blue | B40: 51 | C40: 47 | D40: 50 | E40: 51 | F40: 60 | G40: 259
...
